<?xml version="1.0"?>
<robot name="mercedes_split_tex_control">
  <!-- Minimal control-only URDF for gazebo_ros2_control -->

  <link name="chassis"/>
  <link name="front_left_steer"/>
  <link name="front_right_steer"/>
  <link name="front_left_wheel"/>
  <link name="front_right_wheel"/>
  <link name="rear_left_wheel"/>
  <link name="rear_right_wheel"/>

  <!-- Front steering joints -->
  <joint name="front_left_steer_joint" type="revolute">
    <parent link="chassis"/>
    <child link="front_left_steer"/>
    <origin xyz="0.792 0.1935 0.0975" rpy="0 0 0"/>
    <axis xyz="0 0 1"/>
    <limit lower="-0.4394" upper="0.4394" effort="80" velocity="10"/>
  </joint>

  <joint name="front_right_steer_joint" type="revolute">
    <parent link="chassis"/>
    <child link="front_right_steer"/>
    <origin xyz="0.792 -0.1935 0.0975" rpy="0 0 0"/>
    <axis xyz="0 0 1"/>
    <limit lower="-0.4394" upper="0.4394" effort="80" velocity="10"/>
  </joint>

  <!-- Wheel spin joints -->
  <joint name="front_left_wheel_joint" type="continuous">
    <parent link="front_left_steer"/>
    <child link="front_left_wheel"/>
    <origin xyz="0 0 0" rpy="0 0 0"/>
    <axis xyz="0 -1 0"/>
  </joint>

  <joint name="front_right_wheel_joint" type="continuous">
    <parent link="front_right_steer"/>
    <child link="front_right_wheel"/>
    <origin xyz="0 0 0" rpy="0 0 0"/>
    <axis xyz="0 -1 0"/>
  </joint>

  <joint name="rear_left_wheel_joint" type="continuous">
    <parent link="chassis"/>
    <child link="rear_left_wheel"/>
    <origin xyz="0.18386 0.1935 0.0975" rpy="0 0 0"/>
    <axis xyz="0 -1 0"/>
  </joint>

  <joint name="rear_right_wheel_joint" type="continuous">
    <parent link="chassis"/>
    <child link="rear_right_wheel"/>
    <origin xyz="0.18386 -0.1935 0.0975" rpy="0 0 0"/>
    <axis xyz="0 -1 0"/>
  </joint>

  <ros2_control name="GazeboSystem" type="system">
    <hardware>
      <plugin>gazebo_ros2_control/GazeboSystem</plugin>
    </hardware>

    <joint name="front_left_steer_joint">
      <command_interface name="position">
        <param name="min">-0.4394</param>
        <param name="max">0.4394</param>
      </command_interface>
      <state_interface name="position"/>
      <state_interface name="velocity"/>
    </joint>

    <joint name="front_right_steer_joint">
      <command_interface name="position">
        <param name="min">-0.4394</param>
        <param name="max">0.4394</param>
      </command_interface>
      <state_interface name="position"/>
      <state_interface name="velocity"/>
    </joint>

    <joint name="rear_left_wheel_joint">
      <command_interface name="velocity">
        <param name="min">-12.0</param>
        <param name="max">12.0</param>
      </command_interface>
      <state_interface name="position"/>
      <state_interface name="velocity"/>
    </joint>

    <joint name="rear_right_wheel_joint">
      <command_interface name="velocity">
        <param name="min">-12.0</param>
        <param name="max">12.0</param>
      </command_interface>
      <state_interface name="position"/>
      <state_interface name="velocity"/>
    </joint>

    <!-- Front wheel velocity state is still useful for visualization/debug -->
    <joint name="front_left_wheel_joint">
      <state_interface name="position"/>
      <state_interface name="velocity"/>
    </joint>

    <joint name="front_right_wheel_joint">
      <state_interface name="position"/>
      <state_interface name="velocity"/>
    </joint>
  </ros2_control>
</robot>
